Workbook
Name Опоры_0_4: 'Спр_Опоры'!$B$4:$B$34
Name Опоры_6: 'Спр_Опоры'!$B$35:$B$38
Name Опоры_10: 'Спр_Опоры'!$B$39:$B$98
Name Опоры_10_0_4: 'Спр_Опоры'!$B$99:$B$102
Name Опоры_35: 'Спр_Опоры'!$B$103:$B$126
Name Опоры_110: 'Спр_Опоры'!$B$127:$B$145
Name Подвеска_Марки: 'Спр_Провода'!$F$4:$F$49
Name Приборы_Наим: 'Спр_Приборы'!$A$4:$A$20
Name Приборы_Марки: 'Спр_Приборы'!$B$4:$B$20

Sheet Инструкция
B1: ID_shablon.xlsx — файл исходных данных для отчёта ППО ВОЛС
B2: Отчёт по пункту 13 Правил недискриминационного доступа (ПП РФ от 22.11.2022 № 2106). Книга соответствует рабочему месту версии 3.5.10.
B4: ДВА ЦВЕТА ЯЧЕЕК
B5: ЖЁЛТЫЕ | C5: Заполняете вручную.
B6: ЗЕЛЁНЫЕ | C6: Заполняются формулами. Не трогайте: при вводе своего значения формула стирается безвозвратно.
B7: Треугольник в углу | C7: Выпадающий список. Выбирайте мышкой, не печатайте — иначе автозаполнение не сработает.
B8: Строки ПРИМЕР | C8: Серый курсив, слово ПРИМЕР в последнем столбце. Удалите целиком перед заполнением.
B10: ПОРЯДОК ЗАПОЛНЕНИЯ ЛИСТОВ
B11: 1. Паспорт | C11: Реквизиты запроса, стороны, объект, климат, работы, оформление. Габариты, охранную зону и протяжённость участка не заполняйте — подставятся.
B12: 2. Линии | C12: По строке на каждую ВЛ: инвентарный номер, год ввода, основание права. Наименование линии должно совпадать с листом «Опоры» посимвольно.
B13: 3. Кабели | C13: Что просит разместить оператор. Высота подвеса = нормируемый габарит (5,0 м) ПЛЮС стрела провеса.
B14: 4. Опоры | C14: Сначала класс напряжения, затем марка: перечень марок связан с классом. Координаты обязательны — по ним считаются пролёты и протяжённость.
B15: 5. Измерения | C15: Одна опора + один вид измерения = одна строка. Графа «№ опоры» обязательна, линия выводится от опоры.
B16: 6. СИ | C16: Приборы. Номер записи и дата окончания поверки обязательны. Наименование и марка — из листа «Спр_Приборы».
B17: 7. Нагрузки, Блок 2 | C17: Провода ВЛ, грозотрос, ранее размещённые кабели. Собственные провода ВЛ — обязательно. Марки берутся из сводного перечня «кабели + провода».
B18: 8. Мероприятия | C18: Заполнится само. Вручную — только срок и стоимость.
B20: ЧТО СЧИТАЕТСЯ САМО И ВРУЧНУЮ НЕ ВВОДИТСЯ
B21: Пролёт между опорами | C21: Определяется по координатам опор. Порядок опор в линии тоже строится по координатам, а не по номеру, поэтому одинаковые номера у разных опор расчёту не мешают.
B22: Протяжённость участка | C22: Сумма пролётов по координатам, включая звенья ручной привязки соседей.
B23: Отклонение от вертикали | C23: В поле измеряется УГОЛ. Отклонение верха в миллиметрах и величина 1/N считаются по углу и высоте опоры.
B24: Ранее размещённые ОК | C24: Позиция подвески в Блоке 2 выводится из графы «Существующих подвесов связи» листа «Опоры»: количество — наибольшее число подвесов на опоре класса, характеристики — по типовому самонесущему ОК.
B26: СЛУЖЕБНАЯ ГРАФА ЛИСТА «ОПОРЫ» (последний столбец)
B27: КОНЕЧНАЯ | C27: Опора отмечена как конец участка: пролёт до следующей опоры не считается, цепь на ней обрывается.
B28: СЛЕД=линия|номер | C28: Следующая опора указана вручную — обычно когда продолжение лежит на другой линии или в другом классе напряжения.
B29: ПРЕД=линия|номер | C29: То же для предыдущей опоры. Пролёт всё равно считается по координатам обеих опор.
B30: Графу не правьте руками | C30: Она заполняется рабочим местом и читается им обратно. Признаки задаются в карточке опоры либо в карточке метки на карте.
B32: ЧЕТЫРЕ ОШИБКИ, КОТОРЫЕ ОБЕСЦЕНИВАЮТ ОТЧЁТ
B33: Нет проводов ВЛ в Блоке 2 | C33: Расчёт учтёт только кабели связи и завысит запас несущей способности в разы.
B34: Одно значение на всю линию | C34: Тиражирование замера на десяток опор — формально фальсификация протокола. Измеряйте раздельно.
B35: Высота подвеса 5,0 м | C35: В середине пролёта норматив не будет обеспечен ни при какой стреле провеса.
B36: Дефекты опор — на оператора | C36: Дефекты, возникшие до заявки, устраняет владелец (ст. 210 ГК РФ). Иное — риск по ч. 1 ст. 10 № 135-ФЗ.
B38: ГРАНИЦА ОТЧЁТА И ПРОЕКТНОЙ ДОКУМЕНТАЦИИ
B39: В отчёт входит | C39: Осмотр, инструментальные измерения, учёт ранее размещённых сетей, сводная оценка технологической возможности.
B40: В проект входит | C40: Поверочные расчёты, выбор марок и арматуры, точки и высоты подвеса, стрелы провеса, тяжения, технические решения по дефектам.
B41: Отчёт не является | C41: Результатом инженерных изысканий (ст. 47 ГрК РФ), проектной документацией (ст. 48 ГрК РФ), заключением об обследовании строительных конструкций.
B43: СПРАВОЧНИКИ КНИГИ
B44: Спр_Опоры | C44: 131 марка по типовым проектам, сгруппированы по классу напряжения. Отметка «по аналогии» — расчётные величины приняты по стойке-аналогу и подтверждаются по проекту.
B45: Спр_Кабели / Спр_Провода | C45: Размещаемые ОК и собственные провода ВЛ. Графа F листа «Спр_Провода» — сводный перечень марок для Блока 2.
B46: Спр_Приборы | C46: Средства измерений. Первые строки — приборы подразделения с заводским номером и записью о поверке.
B47: Спр_ВЛ / Спр_Измерения / Спр_Дефекты / Спр_Списки | C47: Константы ПУЭ-7 и ПП № 160, виды измерений, категории дефектов, значения выпадающих списков.
...

Sheet Паспорт
A1: ПАСПОРТ ОБЪЕКТА И РЕКВИЗИТЫ ОТЧЁТА
A3: Код | B3: Наименование поля | C3: Значение
A4: ЗАПРОС ПОЛЬЗОВАТЕЛЯ ИНФРАСТРУКТУРЫ (п. 13 Правил)
A5: ЗАПРОС_НОМЕР | B5: Номер запроса пользователя инфраструктуры | C5: исх. № 04-14/2261
A6: ЗАПРОС_ДАТА | B6: Дата запроса | C6: 02.06.2026
A7: ЗАПРОС_ВХ_НОМЕР | B7: Входящий номер регистрации запроса у владельца | C7: вх. № КЭ/АЭС/1187
A8: ЗАПРОС_ВХ_ДАТА | B8: Дата регистрации запроса | C8: 05.06.2026
A9: КОНФИД_ОБЯЗАТ | B9: Обязательство о конфиденциальности: номер и дата письменного обязательства оператора о неразглашении (обязательное приложение по п. 15 Правил) | C9: обязательство б/н от 02.06.2026
A10: ДОГОВОР_НОМЕР | B10: Договор (счёт) на работы по осмотру, измерению, обследованию (п. 16) | C10: № 23002603002603
A11: ДОГОВОР_ДАТА | B11: Дата договора (счёта) | C11: 25.02.2026
A12: ДОГОВОР_СРОК | B12: Дата исполнения обязательств по договору (счёту) — расчётная предельная дата | C12: 12.08.2026
A13: ОПЛАТА_ДАТА | B13: Дата оплаты работ по осмотру и обследованию (абз. 2 п. 16 Правил) | C13: 26.02.2026
A14: КОНФИД_ПОДПИСАНТ | B14: Обязательство о конфиденциальности — подписант (должность, Ф.И.О.) | C14: генеральный директор ______________
A15: СТОРОНЫ
A16: ВЛАДЕЛЕЦ_НАИМ | B16: Владелец инфраструктуры (полное наименование) | C16: Публичное акционерное общество «Россети Юг»
A17: ВЛАДЕЛЕЦ_ФИЛИАЛ | B17: Филиал / производственное отделение | C17: филиал ПАО «Россети Юг» — «Кубаньэнерго», Армавирские электрические сети
A18: ВЛАДЕЛЕЦ_АДРЕС | B18: Адрес владельца инфраструктуры | C18: 352900, Краснодарский край, г. Армавир, ул. Воровского, 54
A19: ПОЛЬЗОВАТЕЛЬ_НАИМ | B19: Пользователь инфраструктуры (оператор связи) | C19: Общество с ограниченной ответственностью «Защита информации»
A20: ПОЛЬЗОВАТЕЛЬ_АДРЕС | B20: Адрес пользователя инфраструктуры | C20: 350000, г. Краснодар, ул. Красная, 1
A21: ПОЛЬЗОВАТЕЛЬ_РЕКВИЗИТЫ | B21: ОГРН / ИНН пользователя инфраструктуры (для формы обязательства по п. 15 Правил) | C21: ОГРН 1027700000000, ИНН 7700000000
A22: ПОЛЬЗОВАТЕЛЬ_ПОДПИСАНТ_ДОЛЖ | B22: Должность подписанта от пользователя инфраструктуры | C22: генеральный директор
A23: ПОЛЬЗОВАТЕЛЬ_ПОДПИСАНТ_ФИО | B23: Ф.И.О. подписанта от пользователя инфраструктуры | C23: _______________
A24: ПОЛЬЗОВАТЕЛЬ_ОСНОВАНИЕ | B24: Основание полномочий подписанта | C24: устав
A25: ОБЪЕКТ ИНФРАСТРУКТУРЫ
A26: ОБЪЕКТ_ВИД | B26: Вид объекта инфраструктуры (по п. 2 Правил) | C26: сопряжённый объект инфраструктуры — воздушная линия электропередачи
A27: ОБЪЕКТ_НАИМ | B27: Наименование объекта | C27: ВЛ 10 кВ КН-13
A28: ОБЪЕКТ_КЛАСС | B28: Класс(ы) напряжения, кВ — выбрать из списка; при нескольких перечислить через «;» | C28: 10
A29: ОБЪЕКТ_КЛАСС_МАКС | B29: Наибольший класс напряжения, кВ (АВТО — для габаритов и охранной зоны) | C29: =IFERROR(LOOKUP(9E+99,--TRIM(MID(SUBSTITUTE(C28,";",REPT(" ",50)),(ROW(INDIRECT("1:"&(LEN(C28)-LEN(SUBSTITUTE(C28,";",""))+1)))-1)*50+1,50))),C28) -> 10
A30: ОБЪЕКТ_МЕСТО | B30: Место расположения | C30: Краснодарский край, Новокубанский район, г. Новокубанск, МТФ 3 Южная зона, Ленинский путь, в пределах н/п
A31: МЕСТНОСТЬ | B31: Характер местности — выбрать из списка (определяет нормируемые габариты) | C31: населённая
A32: ОБЪЕКТ_ДЛИНА | B32: Протяжённость участка, км (пусто — считается по пролётам) | C32: 1,2
A33: ОБЪЕКТ_ВЛАДЕНИЕ | B33: Основание владения объектом | C33: право собственности, запись ЕГРН от __.__.____ № _____
A34: ГАБАРИТ_ЗЕМЛЯ | B34: Нормируемый габарит провода до земли, м (АВТО по классу и местности) | C34: =IFERROR(VLOOKUP(TEXT(C29,"General"),Спр_ВЛ!$A$3:$G$11,IF(ISNUMBER(SEARCH("ненасел",C31)),3,2),0),"") -> 7
A35: ГАБАРИТ_ОКСН | B35: Нормируемый габарит ОКСН до земли, м (АВТО) | C35: =IFERROR(VLOOKUP(TEXT(C29,"General"),Спр_ВЛ!$A$3:$G$11,4,0),5) -> 5
A36: РАССТ_ОКСН_ПРОВОД | B36: Мин. расстояние ОКСН–провод, м (АВТО по наибольшему классу) | C36: =IFERROR(VLOOKUP(TEXT(C29,"General"),Спр_ВЛ!$A$3:$G$11,5,0),"") -> 0.6
A37: ОХРАННАЯ_ЗОНА | B37: Охранная зона объекта, м (АВТО по наибольшему классу; ПП РФ № 160) | C37: =IFERROR(VLOOKUP(TEXT(C29,"General"),Спр_ВЛ!$A$3:$G$11,6,0),"") -> 10
A38: ОХРАННАЯ_ЗОНА_ТЕКСТ | B38: Охранная зона — текст для отчёта (реквизиты ЕГРН и т.п.) | C38: сведения внесены в ЕГРН, реестровый номер ______
A39: ИНФОСИСТЕМА | B39: Сведения об объекте в информационной системе владельца | C39: внесены / не внесены, идентификатор ______
A40: РЕМОНТ_ПЛАНЫ | B40: Планы ремонта и реконструкции объекта, влияющие на размещение | C40: на дату отчёта работы по реконструкции и техническому перевооружению участка в утверждённых программах не значатся
A41: ЗАЯВКИ_ИНЫЕ | B41: Иные заявки на тот же участок (очерёдность рассмотрения) | C41: иных заявлений о предоставлении доступа к тому же участку на дату отчёта не зарегистрировано
...

Sheet Линии
A1: ЛИНИИ В ГРАНИЦАХ ЗАПРОСА — пообъектная идентификация
A2: Объект «ВЛ 0,4-10 кВ» одним лотом — недопустимое описание: под ним скрывается несколько разных линий с разными инвентарными номерами и основаниями права. Каждая линия описывается отдельной строкой; наименование в графе «Линия / фидер» должно ТОЧНО совпадать с тем, что указано на листе «Опоры», иначе связь не установится.
A3: № п/п | B3: Линия / фидер | C3: Диспетчерское наименование | D3: Инвентарный номер | E3: Год ввода | F3: Класс напряжения, кВ | G3: Основание права (реквизиты) | H3: Планы ремонта и реконструкции | I3: Иные заявки на участок | J3: Опор в границах запроса | K3: Служебная отметка
A4: 1 | B4: ВЛ 10 кВ КН-13 | C4: ВЛ 10 кВ КН-13 от ПС 35/10 кВ «Новокубанская» | D4: 10:00:0000000:1234 | E4: 1986 | F4: 10 | G4: право собственности, запись ЕГРН от __.__.____ № _____ | H4: в утверждённых программах ремонта на текущий год не значится | I4: иных заявлений не зарегистрировано | J4: =IF($B4="","",COUNTIF(Опоры!$B:$B,$B4)) -> 3 | K4: ПРИМЕР
J5: =IF($B5="","",COUNTIF(Опоры!$B:$B,$B5))
J6: =IF($B6="","",COUNTIF(Опоры!$B:$B,$B6))
J7: =IF($B7="","",COUNTIF(Опоры!$B:$B,$B7))
J8: =IF($B8="","",COUNTIF(Опоры!$B:$B,$B8))
J9: =IF($B9="","",COUNTIF(Опоры!$B:$B,$B9))
J10: =IF($B10="","",COUNTIF(Опоры!$B:$B,$B10))
J11: =IF($B11="","",COUNTIF(Опоры!$B:$B,$B11))
J12: =IF($B12="","",COUNTIF(Опоры!$B:$B,$B12))
J13: =IF($B13="","",COUNTIF(Опоры!$B:$B,$B13))
J14: =IF($B14="","",COUNTIF(Опоры!$B:$B,$B14))
J15: =IF($B15="","",COUNTIF(Опоры!$B:$B,$B15))
J16: =IF($B16="","",COUNTIF(Опоры!$B:$B,$B16))
... J33: =IF($B33="","",COUNTIF(Опоры!$B:$B,$B33))

Sheet Кабели
A1: № п/п | B1: Марка (из «Спр_Кабели») | C1: Тип элемента | D1: Наружный диаметр, мм | E1: Погонная масса, кг/км | F1: Допустимое тяжение, кН | G1: Область применения (кВ) | H1: Высота подвеса, м | I1: Линейная арматура | J1: Примечание | K1: Класс напряжения размещения, кВ | L1: Монтажное тяжение, кН | M1: Служебная отметка
A2: 1 | B2: ОКСН-8-4,0 | C2: =IFERROR(VLOOKUP($B2,Спр_Кабели!$A$4:$G$17,2,0),"") -> ОКСН — самонесущий неметаллический | D2: =IFERROR(VLOOKUP($B2,Спр_Кабели!$A$4:$G$17,3,0),"") -> 11.5 | E2: =IFERROR(VLOOKUP($B2,Спр_Кабели!$A$4:$G$17,4,0),"") -> 105 | F2: =IFERROR(VLOOKUP($B2,Спр_Кабели!$A$4:$G$17,5,0),"") -> 4 | G2: =IFERROR(VLOOKUP($B2,Спр_Кабели!$A$4:$G$17,6,0),"") -> 0,4–110 | H2: 6 | I2: спиральная натяжная и поддерживающая, заводская | K2: все классы | L2: =IF($B2="","",IFERROR(VLOOKUP($B2,Спр_Кабели!$A$4:$G$17,5,0),"")) -> 4 | M2: ПРИМЕР
C3: =IFERROR(VLOOKUP($B3,Спр_Кабели!$A$4:$G$17,2,0),"") | D3: =IFERROR(VLOOKUP($B3,Спр_Кабели!$A$4:$G$17,3,0),"") | E3: =IFERROR(VLOOKUP($B3,Спр_Кабели!$A$4:$G$17,4,0),"") | F3: =IFERROR(VLOOKUP($B3,Спр_Кабели!$A$4:$G$17,5,0),"") | G3: =IFERROR(VLOOKUP($B3,Спр_Кабели!$A$4:$G$17,6,0),"") | L3: =IF($B3="","",IFERROR(VLOOKUP($B3,Спр_Кабели!$A$4:$G$17,5,0),""))
C4: =IFERROR(VLOOKUP($B4,Спр_Кабели!$A$4:$G$17,2,0),"") | D4: =IFERROR(VLOOKUP($B4,Спр_Кабели!$A$4:$G$17,3,0),"") | E4: =IFERROR(VLOOKUP($B4,Спр_Кабели!$A$4:$G$17,4,0),"") | F4: =IFERROR(VLOOKUP($B4,Спр_Кабели!$A$4:$G$17,5,0),"") | G4: =IFERROR(VLOOKUP($B4,Спр_Кабели!$A$4:$G$17,6,0),"") | L4: =IF($B4="","",IFERROR(VLOOKUP($B4,Спр_Кабели!$A$4:$G$17,5,0),""))
C5: =IFERROR(VLOOKUP($B5,Спр_Кабели!$A$4:$G$17,2,0),"") | D5: =IFERROR(VLOOKUP($B5,Спр_Кабели!$A$4:$G$17,3,0),"") | E5: =IFERROR(VLOOKUP($B5,Спр_Кабели!$A$4:$G$17,4,0),"") | F5: =IFERROR(VLOOKUP($B5,Спр_Кабели!$A$4:$G$17,5,0),"") | G5: =IFERROR(VLOOKUP($B5,Спр_Кабели!$A$4:$G$17,6,0),"") | L5: =IF($B5="","",IFERROR(VLOOKUP($B5,Спр_Кабели!$A$4:$G$17,5,0),""))
C6: =IFERROR(VLOOKUP($B6,Спр_Кабели!$A$4:$G$17,2,0),"") | D6: =IFERROR(VLOOKUP($B6,Спр_Кабели!$A$4:$G$17,3,0),"") | E6: =IFERROR(VLOOKUP($B6,Спр_Кабели!$A$4:$G$17,4,0),"") | F6: =IFERROR(VLOOKUP($B6,Спр_Кабели!$A$4:$G$17,5,0),"") | G6: =IFERROR(VLOOKUP($B6,Спр_Кабели!$A$4:$G$17,6,0),"") | L6: =IF($B6="","",IFERROR(VLOOKUP($B6,Спр_Кабели!$A$4:$G$17,5,0),""))
C7: =IFERROR(VLOOKUP($B7,Спр_Кабели!$A$4:$G$17,2,0),"") | D7: =IFERROR(VLOOKUP($B7,Спр_Кабели!$A$4:$G$17,3,0),"") | E7: =IFERROR(VLOOKUP($B7,Спр_Кабели!$A$4:$G$17,4,0),"") | F7: =IFERROR(VLOOKUP($B7,Спр_Кабели!$A$4:$G$17,5,0),"") | G7: =IFERROR(VLOOKUP($B7,Спр_Кабели!$A$4:$G$17,6,0),"") | L7: =IF($B7="","",IFERROR(VLOOKUP($B7,Спр_Кабели!$A$4:$G$17,5,0),""))
C8: =IFERROR(VLOOKUP($B8,Спр_Кабели!$A$4:$G$17,2,0),"") | D8: =IFERROR(VLOOKUP($B8,Спр_Кабели!$A$4:$G$17,3,0),"") | E8: =IFERROR(VLOOKUP($B8,Спр_Кабели!$A$4:$G$17,4,0),"") | F8: =IFERROR(VLOOKUP($B8,Спр_Кабели!$A$4:$G$17,5,0),"") | G8: =IFERROR(VLOOKUP($B8,Спр_Кабели!$A$4:$G$17,6,0),"") | L8: =IF($B8="","",IFERROR(VLOOKUP($B8,Спр_Кабели!$A$4:$G$17,5,0),""))
C9: =IFERROR(VLOOKUP($B9,Спр_Кабели!$A$4:$G$17,2,0),"") | D9: =IFERROR(VLOOKUP($B9,Спр_Кабели!$A$4:$G$17,3,0),"") | E9: =IFERROR(VLOOKUP($B9,Спр_Кабели!$A$4:$G$17,4,0),"") | F9: =IFERROR(VLOOKUP($B9,Спр_Кабели!$A$4:$G$17,5,0),"") | G9: =IFERROR(VLOOKUP($B9,Спр_Кабели!$A$4:$G$17,6,0),"") | L9: =IF($B9="","",IFERROR(VLOOKUP($B9,Спр_Кабели!$A$4:$G$17,5,0),""))
C10: =IFERROR(VLOOKUP($B10,Спр_Кабели!$A$4:$G$17,2,0),"") | D10: =IFERROR(VLOOKUP($B10,Спр_Кабели!$A$4:$G$17,3,0),"") | E10: =IFERROR(VLOOKUP($B10,Спр_Кабели!$A$4:$G$17,4,0),"") | F10: =IFERROR(VLOOKUP($B10,Спр_Кабели!$A$4:$G$17,5,0),"") | G10: =IFERROR(VLOOKUP($B10,Спр_Кабели!$A$4:$G$17,6,0),"") | L10: =IF($B10="","",IFERROR(VLOOKUP($B10,Спр_Кабели!$A$4:$G$17,5,0),""))
C11: =IFERROR(VLOOKUP($B11,Спр_Кабели!$A$4:$G$17,2,0),"") | D11: =IFERROR(VLOOKUP($B11,Спр_Кабели!$A$4:$G$17,3,0),"") | E11: =IFERROR(VLOOKUP($B11,Спр_Кабели!$A$4:$G$17,4,0),"") | F11: =IFERROR(VLOOKUP($B11,Спр_Кабели!$A$4:$G$17,5,0),"") | G11: =IFERROR(VLOOKUP($B11,Спр_Кабели!$A$4:$G$17,6,0),"") | L11: =IF($B11="","",IFERROR(VLOOKUP($B11,Спр_Кабели!$A$4:$G$17,5,0),""))
C12: =IFERROR(VLOOKUP($B12,Спр_Кабели!$A$4:$G$17,2,0),"") | D12: =IFERROR(VLOOKUP($B12,Спр_Кабели!$A$4:$G$17,3,0),"") | E12: =IFERROR(VLOOKUP($B12,Спр_Кабели!$A$4:$G$17,4,0),"") | F12: =IFERROR(VLOOKUP($B12,Спр_Кабели!$A$4:$G$17,5,0),"") | G12: =IFERROR(VLOOKUP($B12,Спр_Кабели!$A$4:$G$17,6,0),"") | L12: =IF($B12="","",IFERROR(VLOOKUP($B12,Спр_Кабели!$A$4:$G$17,5,0),""))
C13: =IFERROR(VLOOKUP($B13,Спр_Кабели!$A$4:$G$17,2,0),"") | D13: =IFERROR(VLOOKUP($B13,Спр_Кабели!$A$4:$G$17,3,0),"") | E13: =IFERROR(VLOOKUP($B13,Спр_Кабели!$A$4:$G$17,4,0),"") | F13: =IFERROR(VLOOKUP($B13,Спр_Кабели!$A$4:$G$17,5,0),"") | G13: =IFERROR(VLOOKUP($B13,Спр_Кабели!$A$4:$G$17,6,0),"") | L13: =IF($B13="","",IFERROR(VLOOKUP($B13,Спр_Кабели!$A$4:$G$17,5,0),""))
C14: =IFERROR(VLOOKUP($B14,Спр_Кабели!$A$4:$G$17,2,0),"") | D14: =IFERROR(VLOOKUP($B14,Спр_Кабели!$A$4:$G$17,3,0),"") | E14: =IFERROR(VLOOKUP($B14,Спр_Кабели!$A$4:$G$17,4,0),"") | F14: =IFERROR(VLOOKUP($B14,Спр_Кабели!$A$4:$G$17,5,0),"") | G14: =IFERROR(VLOOKUP($B14,Спр_Кабели!$A$4:$G$17,6,0),"") | L14: =IF($B14="","",IFERROR(VLOOKUP($B14,Спр_Кабели!$A$4:$G$17,5,0),""))
... C20: =IFERROR(VLOOKUP($B20,Спр_Кабели!$A$4:$G$17,2,0),"") | D20: =IFERROR(VLOOKUP($B20,Спр_Кабели!$A$4:$G$17,3,0),"") | E20: =IFERROR(VLOOKUP($B20,Спр_Кабели!$A$4:$G$17,4,0),"") | F20: =IFERROR(VLOOKUP($B20,Спр_Кабели!$A$4:$G$17,5,0),"") | G20: =IFERROR(VLOOKUP($B20,Спр_Кабели!$A$4:$G$17,6,0),"") | L20: =IF($B20="","",IFERROR(VLOOKUP($B20,Спр_Кабели!$A$4:$G$17,5,0),""))

Sheet Опоры
A1: № п/п | B1: Линия / фидер | C1: № опоры | D1: Класс напряжения опоры | E1: Марка опоры | F1: Материал | G1: Тип по назначению | H1: Пролёт до следующей опоры, м | I1: Существующих подвесов связи, шт | J1: Категория дефекта | K1: Дефект | L1: Состояние конструкции (ГОСТ 31937-2024) | M1: Технологическая возможность | N1: Мероприятие | O1: Примечание | P1: Широта | Q1: Долгота | R1: Характер местности | S1: Угол поворота, град | T1: Ранее размещённые ОК — владелец | U1: Ранее размещённые ОК — высота подвеса, м | V1: Габаритный пролёт, м | W1: Служебная отметка
A2: 1 | B2: ВЛ 10 кВ КН-13 | C2: 13 | D2: 10 | E2: П10-1 | F2: =IFERROR(VLOOKUP($E2,Спр_Опоры!$B$4:$J$70,2,0),"") -> Железобетонная | G2: =IFERROR(VLOOKUP($E2,Спр_Опоры!$B$4:$J$70,3,0),"") -> Промежуточная (ненасел.) | H2: 50 | I2: 0 | J2: — | K2: =IFERROR(VLOOKUP($J2,Спр_Дефекты!$A$4:$F$7,2,0),"") -> 0 | L2: =IFERROR(VLOOKUP($J2,Спр_Дефекты!$A$4:$F$7,3,0),"") -> Работоспособное | M2: =IFERROR(VLOOKUP($J2,Спр_Дефекты!$A$4:$F$7,4,0),"") -> есть | N2: =IFERROR(VLOOKUP($J2,Спр_Дефекты!$A$4:$F$7,5,0),"") -> 1 | O2: =IFERROR(VLOOKUP($J2,Спр_Дефекты!$A$4:$F$7,6,0),"") -> 0 | P2: 45.1042 | Q2: 41.0281 | R2: населённая | V2: =IFERROR(VLOOKUP($E2,Спр_Опоры!$B$4:$J$70,9,0),"") -> 60 | W2: ПРИМЕР
A3: 2 | B3: ВЛ 10 кВ КН-13 | C3: 14 | D3: 10 | E3: П10-1 | F3: =IFERROR(VLOOKUP($E3,Спр_Опоры!$B$4:$J$70,2,0),"") -> Железобетонная | G3: =IFERROR(VLOOKUP($E3,Спр_Опоры!$B$4:$J$70,3,0),"") -> Промежуточная (ненасел.) | H3: 48 | I3: 0 | J3: Б | K3: =IFERROR(VLOOKUP($J3,Спр_Дефекты!$A$4:$F$7,2,0),"") -> Отклонение стойки от вертикали сверх допустимого; трещины с раскрытием сверх нормы | L3: =IFERROR(VLOOKUP($J3,Спр_Дефекты!$A$4:$F$7,3,0),"") -> Ограниченно работоспособное | M3: =IFERROR(VLOOKUP($J3,Спр_Дефекты!$A$4:$F$7,4,0),"") -> есть при условии | N3: =IFERROR(VLOOKUP($J3,Спр_Дефекты!$A$4:$F$7,5,0),"") -> 0.8 | O3: =IFERROR(VLOOKUP($J3,Спр_Дефекты!$A$4:$F$7,6,0),"") -> Выправка опоры / усиление (в проектную документацию) | P3: 45.1046 | Q3: 41.0287 | R3: населённая | V3: =IFERROR(VLOOKUP($E3,Спр_Опоры!$B$4:$J$70,9,0),"") -> 60 | W3: ПРИМЕР
A4: 3 | B4: ВЛ 10 кВ КН-13 | C4: 15 | D4: 10 | E4: УА10-1 | F4: =IFERROR(VLOOKUP($E4,Спр_Опоры!$B$4:$J$70,2,0),"") -> Железобетонная | G4: =IFERROR(VLOOKUP($E4,Спр_Опоры!$B$4:$J$70,3,0),"") -> Анкерная угловая (до 90°) | H4: 42 | I4: 1 | J4: A | K4: =IFERROR(VLOOKUP($J4,Спр_Дефекты!$A$4:$F$7,2,0),"") -> Разрушение защитного слоя бетона с обнажением и коррозией арматуры | L4: =IFERROR(VLOOKUP($J4,Спр_Дефекты!$A$4:$F$7,3,0),"") -> Аварийное | M4: =IFERROR(VLOOKUP($J4,Спр_Дефекты!$A$4:$F$7,4,0),"") -> отсутствует | N4: =IFERROR(VLOOKUP($J4,Спр_Дефекты!$A$4:$F$7,5,0),"") -> 0 | O4: =IFERROR(VLOOKUP($J4,Спр_Дефекты!$A$4:$F$7,6,0),"") -> Замена стойки (в проектную документацию) | P4: 45.1051 | Q4: 41.0294 | R4: населённая | S4: 30 | T4: ООО «Оператор» | U4: 6 | V4: =IFERROR(VLOOKUP($E4,Спр_Опоры!$B$4:$J$70,9,0),"") -> 60 | W4: ПРИМЕР
F5: =IFERROR(VLOOKUP($E5,Спр_Опоры!$B$4:$J$70,2,0),"") | G5: =IFERROR(VLOOKUP($E5,Спр_Опоры!$B$4:$J$70,3,0),"") | K5: =IFERROR(VLOOKUP($J5,Спр_Дефекты!$A$4:$F$7,2,0),"") | L5: =IFERROR(VLOOKUP($J5,Спр_Дефекты!$A$4:$F$7,3,0),"") | M5: =IFERROR(VLOOKUP($J5,Спр_Дефекты!$A$4:$F$7,4,0),"") | N5: =IFERROR(VLOOKUP($J5,Спр_Дефекты!$A$4:$F$7,5,0),"") | O5: =IFERROR(VLOOKUP($J5,Спр_Дефекты!$A$4:$F$7,6,0),"") | V5: =IFERROR(VLOOKUP($E5,Спр_Опоры!$B$4:$J$70,9,0),"")
F6: =IFERROR(VLOOKUP($E6,Спр_Опоры!$B$4:$J$70,2,0),"") | G6: =IFERROR(VLOOKUP($E6,Спр_Опоры!$B$4:$J$70,3,0),"") | K6: =IFERROR(VLOOKUP($J6,Спр_Дефекты!$A$4:$F$7,2,0),"") | L6: =IFERROR(VLOOKUP($J6,Спр_Дефекты!$A$4:$F$7,3,0),"") | M6: =IFERROR(VLOOKUP($J6,Спр_Дефекты!$A$4:$F$7,4,0),"") | N6: =IFERROR(VLOOKUP($J6,Спр_Дефекты!$A$4:$F$7,5,0),"") | O6: =IFERROR(VLOOKUP($J6,Спр_Дефекты!$A$4:$F$7,6,0),"") | V6: =IFERROR(VLOOKUP($E6,Спр_Опоры!$B$4:$J$70,9,0),"")
F7: =IFERROR(VLOOKUP($E7,Спр_Опоры!$B$4:$J$70,2,0),"") | G7: =IFERROR(VLOOKUP($E7,Спр_Опоры!$B$4:$J$70,3,0),"") | K7: =IFERROR(VLOOKUP($J7,Спр_Дефекты!$A$4:$F$7,2,0),"") | L7: =IFERROR(VLOOKUP($J7,Спр_Дефекты!$A$4:$F$7,3,0),"") | M7: =IFERROR(VLOOKUP($J7,Спр_Дефекты!$A$4:$F$7,4,0),"") | N7: =IFERROR(VLOOKUP($J7,Спр_Дефекты!$A$4:$F$7,5,0),"") | O7: =IFERROR(VLOOKUP($J7,Спр_Дефекты!$A$4:$F$7,6,0),"") | V7: =IFERROR(VLOOKUP($E7,Спр_Опоры!$B$4:$J$70,9,0),"")
F8: =IFERROR(VLOOKUP($E8,Спр_Опоры!$B$4:$J$70,2,0),"") | G8: =IFERROR(VLOOKUP($E8,Спр_Опоры!$B$4:$J$70,3,0),"") | K8: =IFERROR(VLOOKUP($J8,Спр_Дефекты!$A$4:$F$7,2,0),"") | L8: =IFERROR(VLOOKUP($J8,Спр_Дефекты!$A$4:$F$7,3,0),"") | M8: =IFERROR(VLOOKUP($J8,Спр_Дефекты!$A$4:$F$7,4,0),"") | N8: =IFERROR(VLOOKUP($J8,Спр_Дефекты!$A$4:$F$7,5,0),"") | O8: =IFERROR(VLOOKUP($J8,Спр_Дефекты!$A$4:$F$7,6,0),"") | V8: =IFERROR(VLOOKUP($E8,Спр_Опоры!$B$4:$J$70,9,0),"")
F9: =IFERROR(VLOOKUP($E9,Спр_Опоры!$B$4:$J$70,2,0),"") | G9: =IFERROR(VLOOKUP($E9,Спр_Опоры!$B$4:$J$70,3,0),"") | K9: =IFERROR(VLOOKUP($J9,Спр_Дефекты!$A$4:$F$7,2,0),"") | L9: =IFERROR(VLOOKUP($J9,Спр_Дефекты!$A$4:$F$7,3,0),"") | M9: =IFERROR(VLOOKUP($J9,Спр_Дефекты!$A$4:$F$7,4,0),"") | N9: =IFERROR(VLOOKUP($J9,Спр_Дефекты!$A$4:$F$7,5,0),"") | O9: =IFERROR(VLOOKUP($J9,Спр_Дефекты!$A$4:$F$7,6,0),"") | V9: =IFERROR(VLOOKUP($E9,Спр_Опоры!$B$4:$J$70,9,0),"")
F10: =IFERROR(VLOOKUP($E10,Спр_Опоры!$B$4:$J$70,2,0),"") | G10: =IFERROR(VLOOKUP($E10,Спр_Опоры!$B$4:$J$70,3,0),"") | K10: =IFERROR(VLOOKUP($J10,Спр_Дефекты!$A$4:$F$7,2,0),"") | L10: =IFERROR(VLOOKUP($J10,Спр_Дефекты!$A$4:$F$7,3,0),"") | M10: =IFERROR(VLOOKUP($J10,Спр_Дефекты!$A$4:$F$7,4,0),"") | N10: =IFERROR(VLOOKUP($J10,Спр_Дефекты!$A$4:$F$7,5,0),"") | O10: =IFERROR(VLOOKUP($J10,Спр_Дефекты!$A$4:$F$7,6,0),"") | V10: =IFERROR(VLOOKUP($E10,Спр_Опоры!$B$4:$J$70,9,0),"")
F11: =IFERROR(VLOOKUP($E11,Спр_Опоры!$B$4:$J$70,2,0),"") | G11: =IFERROR(VLOOKUP($E11,Спр_Опоры!$B$4:$J$70,3,0),"") | K11: =IFERROR(VLOOKUP($J11,Спр_Дефекты!$A$4:$F$7,2,0),"") | L11: =IFERROR(VLOOKUP($J11,Спр_Дефекты!$A$4:$F$7,3,0),"") | M11: =IFERROR(VLOOKUP($J11,Спр_Дефекты!$A$4:$F$7,4,0),"") | N11: =IFERROR(VLOOKUP($J11,Спр_Дефекты!$A$4:$F$7,5,0),"") | O11: =IFERROR(VLOOKUP($J11,Спр_Дефекты!$A$4:$F$7,6,0),"") | V11: =IFERROR(VLOOKUP($E11,Спр_Опоры!$B$4:$J$70,9,0),"")
F12: =IFERROR(VLOOKUP($E12,Спр_Опоры!$B$4:$J$70,2,0),"") | G12: =IFERROR(VLOOKUP($E12,Спр_Опоры!$B$4:$J$70,3,0),"") | K12: =IFERROR(VLOOKUP($J12,Спр_Дефекты!$A$4:$F$7,2,0),"") | L12: =IFERROR(VLOOKUP($J12,Спр_Дефекты!$A$4:$F$7,3,0),"") | M12: =IFERROR(VLOOKUP($J12,Спр_Дефекты!$A$4:$F$7,4,0),"") | N12: =IFERROR(VLOOKUP($J12,Спр_Дефекты!$A$4:$F$7,5,0),"") | O12: =IFERROR(VLOOKUP($J12,Спр_Дефекты!$A$4:$F$7,6,0),"") | V12: =IFERROR(VLOOKUP($E12,Спр_Опоры!$B$4:$J$70,9,0),"")
F13: =IFERROR(VLOOKUP($E13,Спр_Опоры!$B$4:$J$70,2,0),"") | G13: =IFERROR(VLOOKUP($E13,Спр_Опоры!$B$4:$J$70,3,0),"") | K13: =IFERROR(VLOOKUP($J13,Спр_Дефекты!$A$4:$F$7,2,0),"") | L13: =IFERROR(VLOOKUP($J13,Спр_Дефекты!$A$4:$F$7,3,0),"") | M13: =IFERROR(VLOOKUP($J13,Спр_Дефекты!$A$4:$F$7,4,0),"") | N13: =IFERROR(VLOOKUP($J13,Спр_Дефекты!$A$4:$F$7,5,0),"") | O13: =IFERROR(VLOOKUP($J13,Спр_Дефекты!$A$4:$F$7,6,0),"") | V13: =IFERROR(VLOOKUP($E13,Спр_Опоры!$B$4:$J$70,9,0),"")
F14: =IFERROR(VLOOKUP($E14,Спр_Опоры!$B$4:$J$70,2,0),"") | G14: =IFERROR(VLOOKUP($E14,Спр_Опоры!$B$4:$J$70,3,0),"") | K14: =IFERROR(VLOOKUP($J14,Спр_Дефекты!$A$4:$F$7,2,0),"") | L14: =IFERROR(VLOOKUP($J14,Спр_Дефекты!$A$4:$F$7,3,0),"") | M14: =IFERROR(VLOOKUP($J14,Спр_Дефекты!$A$4:$F$7,4,0),"") | N14: =IFERROR(VLOOKUP($J14,Спр_Дефекты!$A$4:$F$7,5,0),"") | O14: =IFERROR(VLOOKUP($J14,Спр_Дефекты!$A$4:$F$7,6,0),"") | V14: =IFERROR(VLOOKUP($E14,Спр_Опоры!$B$4:$J$70,9,0),"")
F15: =IFERROR(VLOOKUP($E15,Спр_Опоры!$B$4:$J$70,2,0),"") | G15: =IFERROR(VLOOKUP($E15,Спр_Опоры!$B$4:$J$70,3,0),"") | K15: =IFERROR(VLOOKUP($J15,Спр_Дефекты!$A$4:$F$7,2,0),"") | L15: =IFERROR(VLOOKUP($J15,Спр_Дефекты!$A$4:$F$7,3,0),"") | M15: =IFERROR(VLOOKUP($J15,Спр_Дефекты!$A$4:$F$7,4,0),"") | N15: =IFERROR(VLOOKUP($J15,Спр_Дефекты!$A$4:$F$7,5,0),"") | O15: =IFERROR(VLOOKUP($J15,Спр_Дефекты!$A$4:$F$7,6,0),"") | V15: =IFERROR(VLOOKUP($E15,Спр_Опоры!$B$4:$J$70,9,0),"")
F16: =IFERROR(VLOOKUP($E16,Спр_Опоры!$B$4:$J$70,2,0),"") | G16: =IFERROR(VLOOKUP($E16,Спр_Опоры!$B$4:$J$70,3,0),"") | K16: =IFERROR(VLOOKUP($J16,Спр_Дефекты!$A$4:$F$7,2,0),"") | L16: =IFERROR(VLOOKUP($J16,Спр_Дефекты!$A$4:$F$7,3,0),"") | M16: =IFERROR(VLOOKUP($J16,Спр_Дефекты!$A$4:$F$7,4,0),"") | N16: =IFERROR(VLOOKUP($J16,Спр_Дефекты!$A$4:$F$7,5,0),"") | O16: =IFERROR(VLOOKUP($J16,Спр_Дефекты!$A$4:$F$7,6,0),"") | V16: =IFERROR(VLOOKUP($E16,Спр_Опоры!$B$4:$J$70,9,0),"")
... F202: =IFERROR(VLOOKUP($E202,Спр_Опоры!$B$4:$J$70,2,0),"") | G202: =IFERROR(VLOOKUP($E202,Спр_Опоры!$B$4:$J$70,3,0),"") | K202: =IFERROR(VLOOKUP($J202,Спр_Дефекты!$A$4:$F$7,2,0),"") | L202: =IFERROR(VLOOKUP($J202,Спр_Дефекты!$A$4:$F$7,3,0),"") | M202: =IFERROR(VLOOKUP($J202,Спр_Дефекты!$A$4:$F$7,4,0),"") | N202: =IFERROR(VLOOKUP($J202,Спр_Дефекты!$A$4:$F$7,5,0),"") | O202: =IFERROR(VLOOKUP($J202,Спр_Дефекты!$A$4:$F$7,6,0),"") | V202: =IFERROR(VLOOKUP($E202,Спр_Опоры!$B$4:$J$70,9,0),"")

Sheet Измерения
A1: № опоры | B1: Линия / фидер | C1: Вид измерения | D1: Место (отметка), м | E1: Значение | F1: Ед. изм. | G1: Нормативное требование | H1: Вывод | I1: Средство измерения | J1: Раздел протокола | K1: Служебная отметка
A2: 13 | B2: ВЛ 10 кВ КН-13 | C2: Прочность бетона на сжатие (ударный импульс) | D2: =IFERROR(VLOOKUP($C2,Спр_Измерения!$A$4:$F$16,2,0),"") -> 1,2 м | E2: =IFERROR(VLOOKUP($C2,Спр_Измерения!$A$4:$F$16,3,0),"") -> Фактическая прочность, МПа; Проектный класс бетона (число, МПа) | F2: =IFERROR(VLOOKUP($C2,Спр_Измерения!$A$4:$F$16,4,0),"") -> 35 | G2: =IFERROR(VLOOKUP($C2,Спр_Измерения!$A$4:$F$16,5,0),"") -> МПа | H2: =IFERROR(VLOOKUP($C2,Спр_Измерения!$A$4:$G$16,6,0),"") -> не ниже проектного класса бетона B30 (ГОСТ 22690-2015) | I2: ИПС-МГ4.01 | J2: ПРИМЕР
A3: 13 | B3: ВЛ 10 кВ КН-13 | C3: Отклонение стойки от вертикали | D3: =IFERROR(VLOOKUP($C2,Спр_Измерения!$A$4:$F$16,2,0),"") -> 1,2 м | E3: =IFERROR(VLOOKUP($C3,Спр_Измерения!$A$4:$F$16,3,0),"") -> Угол отклонения от вертикали, град; Высота опоры (надземная часть), м | F3: =IFERROR(VLOOKUP($C3,Спр_Измерения!$A$4:$F$16,4,0),"") -> 1/115 | G3: =IFERROR(VLOOKUP($C3,Спр_Измерения!$A$4:$F$16,5,0),"") -> — | H3: =IFERROR(VLOOKUP($C2,Спр_Измерения!$A$4:$G$16,6,0),"") -> не ниже проектного класса бетона B30 (ГОСТ 22690-2015) | I3: РГК Т-05 | J3: ПРИМЕР
A4: 13 | B4: ВЛ 10 кВ КН-13 | C4: Габарит нижнего провода до земли | D4: =IFERROR(VLOOKUP($C3,Спр_Измерения!$A$4:$F$16,2,0),"") -> вершина | E4: =IFERROR(VLOOKUP($C3,Спр_Измерения!$A$4:$F$16,3,0),"") -> Угол отклонения от вертикали, град; Высота опоры (надземная часть), м | F4: =IFERROR(VLOOKUP($C3,Спр_Измерения!$A$4:$F$16,4,0),"") -> 1/115 | G4: =IFERROR(VLOOKUP($C3,Спр_Измерения!$A$4:$F$16,5,0),"") -> — | H4: =IFERROR(VLOOKUP($C3,Спр_Измерения!$A$4:$G$16,6,0),"") -> не более 1/100 высоты опоры (ГОСТ 31937-2024, СП 20.13330.2016) | I4: РГК Т-05 | J4: ПРИМЕР
A5: 14 | B5: ВЛ 10 кВ КН-13 | C5: Отклонение стойки от вертикали | D5: =IFERROR(VLOOKUP($C3,Спр_Измерения!$A$4:$F$16,2,0),"") -> вершина | E5: 1/85 | F5: =IFERROR(VLOOKUP($C3,Спр_Измерения!$A$4:$F$16,4,0),"") -> 1/115 | G5: =IFERROR(VLOOKUP($C3,Спр_Измерения!$A$4:$F$16,5,0),"") -> — | H5: не соответствует | I5: РГК Т-05 | J5: ПРИМЕР
D6: =IFERROR(VLOOKUP($C6,Спр_Измерения!$A$4:$F$16,2,0),"") | E6: =IFERROR(VLOOKUP($C6,Спр_Измерения!$A$4:$F$16,3,0),"") | F6: =IFERROR(VLOOKUP($C6,Спр_Измерения!$A$4:$F$16,4,0),"") | G6: =IFERROR(VLOOKUP($C6,Спр_Измерения!$A$4:$F$16,5,0),"") | H6: =IFERROR(VLOOKUP($C6,Спр_Измерения!$A$4:$G$16,6,0),"") | J6: =IFERROR(VLOOKUP($C6,Спр_Измерения!$A$4:$G$16,7,0),"")
D7: =IFERROR(VLOOKUP($C7,Спр_Измерения!$A$4:$F$16,2,0),"") | E7: =IFERROR(VLOOKUP($C7,Спр_Измерения!$A$4:$F$16,3,0),"") | F7: =IFERROR(VLOOKUP($C7,Спр_Измерения!$A$4:$F$16,4,0),"") | G7: =IFERROR(VLOOKUP($C7,Спр_Измерения!$A$4:$F$16,5,0),"") | H7: =IFERROR(VLOOKUP($C7,Спр_Измерения!$A$4:$G$16,6,0),"") | J7: =IFERROR(VLOOKUP($C7,Спр_Измерения!$A$4:$G$16,7,0),"")
D8: =IFERROR(VLOOKUP($C8,Спр_Измерения!$A$4:$F$16,2,0),"") | E8: =IFERROR(VLOOKUP($C8,Спр_Измерения!$A$4:$F$16,3,0),"") | F8: =IFERROR(VLOOKUP($C8,Спр_Измерения!$A$4:$F$16,4,0),"") | G8: =IFERROR(VLOOKUP($C8,Спр_Измерения!$A$4:$F$16,5,0),"") | H8: =IFERROR(VLOOKUP($C8,Спр_Измерения!$A$4:$G$16,6,0),"") | J8: =IFERROR(VLOOKUP($C8,Спр_Измерения!$A$4:$G$16,7,0),"")
D9: =IFERROR(VLOOKUP($C9,Спр_Измерения!$A$4:$F$16,2,0),"") | E9: =IFERROR(VLOOKUP($C9,Спр_Измерения!$A$4:$F$16,3,0),"") | F9: =IFERROR(VLOOKUP($C9,Спр_Измерения!$A$4:$F$16,4,0),"") | G9: =IFERROR(VLOOKUP($C9,Спр_Измерения!$A$4:$F$16,5,0),"") | H9: =IFERROR(VLOOKUP($C9,Спр_Измерения!$A$4:$G$16,6,0),"") | J9: =IFERROR(VLOOKUP($C9,Спр_Измерения!$A$4:$G$16,7,0),"")
D10: =IFERROR(VLOOKUP($C10,Спр_Измерения!$A$4:$F$16,2,0),"") | E10: =IFERROR(VLOOKUP($C10,Спр_Измерения!$A$4:$F$16,3,0),"") | F10: =IFERROR(VLOOKUP($C10,Спр_Измерения!$A$4:$F$16,4,0),"") | G10: =IFERROR(VLOOKUP($C10,Спр_Измерения!$A$4:$F$16,5,0),"") | H10: =IFERROR(VLOOKUP($C10,Спр_Измерения!$A$4:$G$16,6,0),"") | J10: =IFERROR(VLOOKUP($C10,Спр_Измерения!$A$4:$G$16,7,0),"")
D11: =IFERROR(VLOOKUP($C11,Спр_Измерения!$A$4:$F$16,2,0),"") | E11: =IFERROR(VLOOKUP($C11,Спр_Измерения!$A$4:$F$16,3,0),"") | F11: =IFERROR(VLOOKUP($C11,Спр_Измерения!$A$4:$F$16,4,0),"") | G11: =IFERROR(VLOOKUP($C11,Спр_Измерения!$A$4:$F$16,5,0),"") | H11: =IFERROR(VLOOKUP($C11,Спр_Измерения!$A$4:$G$16,6,0),"") | J11: =IFERROR(VLOOKUP($C11,Спр_Измерения!$A$4:$G$16,7,0),"")
D12: =IFERROR(VLOOKUP($C12,Спр_Измерения!$A$4:$F$16,2,0),"") | E12: =IFERROR(VLOOKUP($C12,Спр_Измерения!$A$4:$F$16,3,0),"") | F12: =IFERROR(VLOOKUP($C12,Спр_Измерения!$A$4:$F$16,4,0),"") | G12: =IFERROR(VLOOKUP($C12,Спр_Измерения!$A$4:$F$16,5,0),"") | H12: =IFERROR(VLOOKUP($C12,Спр_Измерения!$A$4:$G$16,6,0),"") | J12: =IFERROR(VLOOKUP($C12,Спр_Измерения!$A$4:$G$16,7,0),"")
D13: =IFERROR(VLOOKUP($C13,Спр_Измерения!$A$4:$F$16,2,0),"") | E13: =IFERROR(VLOOKUP($C13,Спр_Измерения!$A$4:$F$16,3,0),"") | F13: =IFERROR(VLOOKUP($C13,Спр_Измерения!$A$4:$F$16,4,0),"") | G13: =IFERROR(VLOOKUP($C13,Спр_Измерения!$A$4:$F$16,5,0),"") | H13: =IFERROR(VLOOKUP($C13,Спр_Измерения!$A$4:$G$16,6,0),"") | J13: =IFERROR(VLOOKUP($C13,Спр_Измерения!$A$4:$G$16,7,0),"")
D14: =IFERROR(VLOOKUP($C14,Спр_Измерения!$A$4:$F$16,2,0),"") | E14: =IFERROR(VLOOKUP($C14,Спр_Измерения!$A$4:$F$16,3,0),"") | F14: =IFERROR(VLOOKUP($C14,Спр_Измерения!$A$4:$F$16,4,0),"") | G14: =IFERROR(VLOOKUP($C14,Спр_Измерения!$A$4:$F$16,5,0),"") | H14: =IFERROR(VLOOKUP($C14,Спр_Измерения!$A$4:$G$16,6,0),"") | J14: =IFERROR(VLOOKUP($C14,Спр_Измерения!$A$4:$G$16,7,0),"")
D15: =IFERROR(VLOOKUP($C15,Спр_Измерения!$A$4:$F$16,2,0),"") | E15: =IFERROR(VLOOKUP($C15,Спр_Измерения!$A$4:$F$16,3,0),"") | F15: =IFERROR(VLOOKUP($C15,Спр_Измерения!$A$4:$F$16,4,0),"") | G15: =IFERROR(VLOOKUP($C15,Спр_Измерения!$A$4:$F$16,5,0),"") | H15: =IFERROR(VLOOKUP($C15,Спр_Измерения!$A$4:$G$16,6,0),"") | J15: =IFERROR(VLOOKUP($C15,Спр_Измерения!$A$4:$G$16,7,0),"")
D16: =IFERROR(VLOOKUP($C16,Спр_Измерения!$A$4:$F$16,2,0),"") | E16: =IFERROR(VLOOKUP($C16,Спр_Измерения!$A$4:$F$16,3,0),"") | F16: =IFERROR(VLOOKUP($C16,Спр_Измерения!$A$4:$F$16,4,0),"") | G16: =IFERROR(VLOOKUP($C16,Спр_Измерения!$A$4:$F$16,5,0),"") | H16: =IFERROR(VLOOKUP($C16,Спр_Измерения!$A$4:$G$16,6,0),"") | J16: =IFERROR(VLOOKUP($C16,Спр_Измерения!$A$4:$G$16,7,0),"")
D17: =IFERROR(VLOOKUP($C17,Спр_Измерения!$A$4:$F$16,2,0),"") | E17: =IFERROR(VLOOKUP($C17,Спр_Измерения!$A$4:$F$16,3,0),"") | F17: =IFERROR(VLOOKUP($C17,Спр_Измерения!$A$4:$F$16,4,0),"") | G17: =IFERROR(VLOOKUP($C17,Спр_Измерения!$A$4:$F$16,5,0),"") | H17: =IFERROR(VLOOKUP($C17,Спр_Измерения!$A$4:$G$16,6,0),"") | J17: =IFERROR(VLOOKUP($C17,Спр_Измерения!$A$4:$G$16,7,0),"")
... D202: =IFERROR(VLOOKUP($C202,Спр_Измерения!$A$4:$F$16,2,0),"") | E202: =IFERROR(VLOOKUP($C202,Спр_Измерения!$A$4:$F$16,3,0),"") | F202: =IFERROR(VLOOKUP($C202,Спр_Измерения!$A$4:$F$16,4,0),"") | G202: =IFERROR(VLOOKUP($C202,Спр_Измерения!$A$4:$F$16,5,0),"") | H202: =IFERROR(VLOOKUP($C202,Спр_Измерения!$A$4:$G$16,6,0),"") | J202: =IFERROR(VLOOKUP($C202,Спр_Измерения!$A$4:$G$16,7,0),"")

Sheet СИ
A1: Наименование средства измерения | B1: Тип / марка | C1: Заводской № | D1: № записи о поверке во ФГИС «Аршин» | E1: Дата поверки | F1: Поверка действительна до | G1: Служебная отметка
A2: Измеритель прочности бетона | B2: ИПС-МГ4.01 | C2: 10819 | D2: П-431-2026 | E2: 46224 | F2: 46589 | G2: ПРИМЕР
A3: Тахеометр электронный | B3: РГК Т-05 | C3: 611010 | D3: С-ДЮП/27-08-2026/554012358 | E3: 46261 | F3: 46625 | G3: ПРИМЕР

Sheet Мероприятия
A1: № п/п | B1: Группа | C1: Линия / фидер | D1: № опоры | E1: Мероприятие | F1: Основание (дефект, несоответствие) | G1: Исполнитель | H1: Срок выполнения | I1: Ориентировочная стоимость, руб. с НДС
A2: Лист формируется АВТОМАТИЧЕСКИ. Группа Е.2 — устранение дефектов эксплуатации, существовавших до заявки и размещением не вызванных: обязанность владельца (ст. 210 ГК РФ, ПТЭ). Группа Е.1 — мероприятия, обусловленные размещением: обязанность пользователя. Возложение мероприятий группы Е.2 на заявителя как условия доступа образует состав по ч. 1 ст. 10 Федерального закона № 135-ФЗ.
A3: =IF(IFERROR(_xludf.AGGREGATE(15,6,ROW(Измерения!$H$2:$H$202)/((Измерения!$H$2:$H$202="не соответствует")+(Измерения!$H$2:$H$202="недостаточно")),1),"")="","",1) | B3: =IF(IFERROR(_xludf.AGGREGATE(15,6,ROW(Измерения!$H$2:$H$202)/((Измерения!$H$2:$H$202="не соответствует")+(Измерения!$H$2:$H$202="недостаточно")),1),"")="","",IF(IF(INDEX(Измерения!$J:$J,IFERROR(_xludf.AGGREGATE(15,6,ROW(Измерения!$H$2:$H$202)/((Измерения!$H$2:$H$202="не соответствует")+(Измерения!$H$2:$H$202="недостаточно")),1),""))="Г.2 — достаточность интервалов",1,0)=1,"Е.1 — обусловлено размещением (пользователь)","Е.2 — эксплуатация (владелец)")) | C3: =IFERROR(INDEX(Измерения!$B:$B,IFERROR(_xludf.AGGREGATE(15,6,ROW(Измерения!$H$2:$H$202)/((Измерения!$H$2:$H$202="не соответствует")+(Измерения!$H$2:$H$202="недостаточно")),1),"")),"") | D3: =IFERROR(INDEX(Измерения!$A:$A,IFERROR(_xludf.AGGREGATE(15,6,ROW(Измерения!$H$2:$H$202)/((Измерения!$H$2:$H$202="не соответствует")+(Измерения!$H$2:$H$202="недостаточно")),1),"")),"") | E3: =IF(IFERROR(_xludf.AGGREGATE(15,6,ROW(Измерения!$H$2:$H$202)/((Измерения!$H$2:$H$202="не соответствует")+(Измерения!$H$2:$H$202="недостаточно")),1),"")="","",IF(IF(INDEX(Измерения!$J:$J,IFERROR(_xludf.AGGREGATE(15,6,ROW(Измерения!$H$2:$H$202)/((Измерения!$H$2:$H$202="не соответствует")+(Измерения!$H$2:$H$202="недостаточно")),1),""))="Г.2 — достаточность интервалов",1,0)=1,"Проектное решение по размещению ОК с обеспечением нормируемого расстояния","Устранение несоответствия фактического состояния конструкции")) | F3: =IFERROR(INDEX(Измерения!$C:$C,IFERROR(_xludf.AGGREGATE(15,6,ROW(Измерения!$H$2:$H$202)/((Измерения!$H$2:$H$202="не соответствует")+(Измерения!$H$2:$H$202="недостаточно")),1),""))&": "&INDEX(Измерения!$E:$E,IFERROR(_xludf.AGGREGATE(15,6,ROW(Измерения!$H$2:$H$202)/((Измерения!$H$2:$H$202="не соответствует")+(Измерения!$H$2:$H$202="недостаточно")),1),""))&" "&INDEX(Измерения!$F:$F,IFERROR(_xludf.AGGREGATE(15,6,ROW(Измерения!$H$2:$H$202)/((Измерения!$H$2:$H$202="не соответствует")+(Измерения!$H$2:$H$202="недостаточно")),1),""))&" при норме — "&INDEX(Измерения!$G:$G,IFERROR(_xludf.AGGREGATE(15,6,ROW(Измерения!$H$2:$H$202)/((Измерения!$H$2:$H$202="не соответствует")+(Измерения!$H$2:$H$202="недостаточно")),1),"")),"") | G3: =IF(IFERROR(_xludf.AGGREGATE(15,6,ROW(Измерения!$H$2:$H$202)/((Измерения!$H$2:$H$202="не соответствует")+(Измерения!$H$2:$H$202="недостаточно")),1),"")="","",IF(IF(INDEX(Измерения!$J:$J,IFERROR(_xludf.AGGREGATE(15,6,ROW(Измерения!$H$2:$H$202)/((Измерения!$H$2:$H$202="не соответствует")+(Измерения!$H$2:$H$202="недостаточно")),1),""))="Г.2 — достаточность интервалов",1,0)=1,"Пользователь инфраструктуры","Владелец инфраструктуры"))
A4: =IF(IFERROR(_xludf.AGGREGATE(15,6,ROW(Измерения!$H$2:$H$202)/((Измерения!$H$2:$H$202="не соответствует")+(Измерения!$H$2:$H$202="недостаточно")),2),"")="","",2) | B4: =IF(IFERROR(_xludf.AGGREGATE(15,6,ROW(Измерения!$H$2:$H$202)/((Измерения!$H$2:$H$202="не соответствует")+(Измерения!$H$2:$H$202="недостаточно")),2),"")="","",IF(IF(INDEX(Измерения!$J:$J,IFERROR(_xludf.AGGREGATE(15,6,ROW(Измерения!$H$2:$H$202)/((Измерения!$H$2:$H$202="не соответствует")+(Измерения!$H$2:$H$202="недостаточно")),2),""))="Г.2 — достаточность интервалов",1,0)=1,"Е.1 — обусловлено размещением (пользователь)","Е.2 — эксплуатация (владелец)")) | C4: =IFERROR(INDEX(Измерения!$B:$B,IFERROR(_xludf.AGGREGATE(15,6,ROW(Измерения!$H$2:$H$202)/((Измерения!$H$2:$H$202="не соответствует")+(Измерения!$H$2:$H$202="недостаточно")),2),"")),"") | D4: =IFERROR(INDEX(Измерения!$A:$A,IFERROR(_xludf.AGGREGATE(15,6,ROW(Измерения!$H$2:$H$202)/((Измерения!$H$2:$H$202="не соответствует")+(Измерения!$H$2:$H$202="недостаточно")),2),"")),"") | E4: =IF(IFERROR(_xludf.AGGREGATE(15,6,ROW(Измерения!$H$2:$H$202)/((Измерения!$H$2:$H$202="не соответствует")+(Измерения!$H$2:$H$202="недостаточно")),2),"")="","",IF(IF(INDEX(Измерения!$J:$J,IFERROR(_xludf.AGGREGATE(15,6,ROW(Измерения!$H$2:$H$202)/((Измерения!$H$2:$H$202="не соответствует")+(Измерения!$H$2:$H$202="недостаточно")),2),""))="Г.2 — достаточность интервалов",1,0)=1,"Проектное решение по размещению ОК с обеспечением нормируемого расстояния","Устранение несоответствия фактического состояния конструкции")) | F4: =IFERROR(INDEX(Измерения!$C:$C,IFERROR(_xludf.AGGREGATE(15,6,ROW(Измерения!$H$2:$H$202)/((Измерения!$H$2:$H$202="не соответствует")+(Измерения!$H$2:$H$202="недостаточно")),2),""))&": "&INDEX(Измерения!$E:$E,IFERROR(_xludf.AGGREGATE(15,6,ROW(Измерения!$H$2:$H$202)/((Измерения!$H$2:$H$202="не соответствует")+(Измерения!$H$2:$H$202="недостаточно")),2),""))&" "&INDEX(Измерения!$F:$F,IFERROR(_xludf.AGGREGATE(15,6,ROW(Измерения!$H$2:$H$202)/((Измерения!$H$2:$H$202="не соответствует")+(Измерения!$H$2:$H$202="недостаточно")),2),""))&" при норме — "&INDEX(Измерения!$G:$G,IFERROR(_xludf.AGGREGATE(15,6,ROW(Измерения!$H$2:$H$202)/((Измерения!$H$2:$H$202="не соответствует")+(Измерения!$H$2:$H$202="недостаточно")),2),"")),"") | G4: =IF(IFERROR(_xludf.AGGREGATE(15,6,ROW(Измерения!$H$2:$H$202)/((Измерения!$H$2:$H$202="не соответствует")+(Измерения!$H$2:$H$202="недостаточно")),2),"")="","",IF(IF(INDEX(Измерения!$J:$J,IFERROR(_xludf.AGGREGATE(15,6,ROW(Измерения!$H$2:$H$202)/((Измерения!$H$2:$H$202="не соответствует")+(Измерения!$H$2:$H$202="недостаточно")),2),""))="Г.2 — достаточность интервалов",1,0)=1,"Пользователь инфраструктуры","Владелец инфраструктуры"))
A5: =IF(IFERROR(_xludf.AGGREGATE(15,6,ROW(Измерения!$H$2:$H$202)/((Измерения!$H$2:$H$202="не соответствует")+(Измерения!$H$2:$H$202="недостаточно")),3),"")="","",3) | B5: =IF(IFERROR(_xludf.AGGREGATE(15,6,ROW(Измерения!$H$2:$H$202)/((Измерения!$H$2:$H$202="не соответствует")+(Измерения!$H$2:$H$202="недостаточно")),3),"")="","",IF(IF(INDEX(Измерения!$J:$J,IFERROR(_xludf.AGGREGATE(15,6,ROW(Измерения!$H$2:$H$202)/((Измерения!$H$2:$H$202="не соответствует")+(Измерения!$H$2:$H$202="недостаточно")),3),""))="Г.2 — достаточность интервалов",1,0)=1,"Е.1 — обусловлено размещением (пользователь)","Е.2 — эксплуатация (владелец)")) | C5: =IFERROR(INDEX(Измерения!$B:$B,IFERROR(_xludf.AGGREGATE(15,6,ROW(Измерения!$H$2:$H$202)/((Измерения!$H$2:$H$202="не соответствует")+(Измерения!$H$2:$H$202="недостаточно")),3),"")),"") | D5: =IFERROR(INDEX(Измерения!$A:$A,IFERROR(_xludf.AGGREGATE(15,6,ROW(Измерения!$H$2:$H$202)/((Измерения!$H$2:$H$202="не соответствует")+(Измерения!$H$2:$H$202="недостаточно")),3),"")),"") | E5: =IF(IFERROR(_xludf.AGGREGATE(15,6,ROW(Измерения!$H$2:$H$202)/((Измерения!$H$2:$H$202="не соответствует")+(Измерения!$H$2:$H$202="недостаточно")),3),"")="","",IF(IF(INDEX(Измерения!$J:$J,IFERROR(_xludf.AGGREGATE(15,6,ROW(Измерения!$H$2:$H$202)/((Измерения!$H$2:$H$202="не соответствует")+(Измерения!$H$2:$H$202="недостаточно")),3),""))="Г.2 — достаточность интервалов",1,0)=1,"Проектное решение по размещению ОК с обеспечением нормируемого расстояния","Устранение несоответствия фактического состояния конструкции")) | F5: =IFERROR(INDEX(Измерения!$C:$C,IFERROR(_xludf.AGGREGATE(15,6,ROW(Измерения!$H$2:$H$202)/((Измерения!$H$2:$H$202="не соответствует")+(Измерения!$H$2:$H$202="недостаточно")),3),""))&": "&INDEX(Измерения!$E:$E,IFERROR(_xludf.AGGREGATE(15,6,ROW(Измерения!$H$2:$H$202)/((Измерения!$H$2:$H$202="не соответствует")+(Измерения!$H$2:$H$202="недостаточно")),3),""))&" "&INDEX(Измерения!$F:$F,IFERROR(_xludf.AGGREGATE(15,6,ROW(Измерения!$H$2:$H$202)/((Измерения!$H$2:$H$202="не соответствует")+(Измерения!$H$2:$H$202="недостаточно")),3),""))&" при норме — "&INDEX(Измерения!$G:$G,IFERROR(_xludf.AGGREGATE(15,6,ROW(Измерения!$H$2:$H$202)/((Измерения!$H$2:$H$202="не соответствует")+(Измерения!$H$2:$H$202="недостаточно")),3),"")),"") | G5: =IF(IFERROR(_xludf.AGGREGATE(15,6,ROW(Измерения!$H$2:$H$202)/((Измерения!$H$2:$H$202="не соответствует")+(Измерения!$H$2:$H$202="недостаточно")),3),"")="","",IF(IF(INDEX(Измерения!$J:$J,IFERROR(_xludf.AGGREGATE(15,6,ROW(Измерения!$H$2:$H$202)/((Измерения!$H$2:$H$202="не соответствует")+(Измерения!$H$2:$H$202="недостаточно")),3),""))="Г.2 — достаточность интервалов",1,0)=1,"Пользователь инфраструктуры","Владелец инфраструктуры"))
A6: =IF(IFERROR(_xludf.AGGREGATE(15,6,ROW(Измерения!$H$2:$H$202)/((Измерения!$H$2:$H$202="не соответствует")+(Измерения!$H$2:$H$202="недостаточно")),4),"")="","",4) | B6: =IF(IFERROR(_xludf.AGGREGATE(15,6,ROW(Измерения!$H$2:$H$202)/((Измерения!$H$2:$H$202="не соответствует")+(Измерения!$H$2:$H$202="недостаточно")),4),"")="","",IF(IF(INDEX(Измерения!$J:$J,IFERROR(_xludf.AGGREGATE(15,6,ROW(Измерения!$H$2:$H$202)/((Измерения!$H$2:$H$202="не соответствует")+(Измерения!$H$2:$H$202="недостаточно")),4),""))="Г.2 — достаточность интервалов",1,0)=1,"Е.1 — обусловлено размещением (пользователь)","Е.2 — эксплуатация (владелец)")) | C6: =IFERROR(INDEX(Измерения!$B:$B,IFERROR(_xludf.AGGREGATE(15,6,ROW(Измерения!$H$2:$H$202)/((Измерения!$H$2:$H$202="не соответствует")+(Измерения!$H$2:$H$202="недостаточно")),4),"")),"") | D6: =IFERROR(INDEX(Измерения!$A:$A,IFERROR(_xludf.AGGREGATE(15,6,ROW(Измерения!$H$2:$H$202)/((Измерения!$H$2:$H$202="не соответствует")+(Измерения!$H$2:$H$202="недостаточно")),4),"")),"") | E6: =IF(IFERROR(_xludf.AGGREGATE(15,6,ROW(Измерения!$H$2:$H$202)/((Измерения!$H$2:$H$202="не соответствует")+(Измерения!$H$2:$H$202="недостаточно")),4),"")="","",IF(IF(INDEX(Измерения!$J:$J,IFERROR(_xludf.AGGREGATE(15,6,ROW(Измерения!$H$2:$H$202)/((Измерения!$H$2:$H$202="не соответствует")+(Измерения!$H$2:$H$202="недостаточно")),4),""))="Г.2 — достаточность интервалов",1,0)=1,"Проектное решение по размещению ОК с обеспечением нормируемого расстояния","Устранение несоответствия фактического состояния конструкции")) | F6: =IFERROR(INDEX(Измерения!$C:$C,IFERROR(_xludf.AGGREGATE(15,6,ROW(Измерения!$H$2:$H$202)/((Измерения!$H$2:$H$202="не соответствует")+(Измерения!$H$2:$H$202="недостаточно")),4),""))&": "&INDEX(Измерения!$E:$E,IFERROR(_xludf.AGGREGATE(15,6,ROW(Измерения!$H$2:$H$202)/((Измерения!$H$2:$H$202="не соответствует")+(Измерения!$H$2:$H$202="недостаточно")),4),""))&" "&INDEX(Измерения!$F:$F,IFERROR(_xludf.AGGREGATE(15,6,ROW(Измерения!$H$2:$H$202)/((Измерения!$H$2:$H$202="не соответствует")+(Измерения!$H$2:$H$202="недостаточно")),4),""))&" при норме — "&INDEX(Измерения!$G:$G,IFERROR(_xludf.AGGREGATE(15,6,ROW(Измерения!$H$2:$H$202)/((Измерения!$H$2:$H$202="не соответствует")+(Измерения!$H$2:$H$202="недостаточно")),4),"")),"") | G6: =IF(IFERROR(_xludf.AGGREGATE(15,6,ROW(Измерения!$H$2:$H$202)/((Измерения!$H$2:$H$202="не соответствует")+(Измерения!$H$2:$H$202="недостаточно")),4),"")="","",IF(IF(INDEX(Измерения!$J:$J,IFERROR(_xludf.AGGREGATE(15,6,ROW(Измерения!$H$2:$H$202)/((Измерения!$H$2:$H$202="не соответствует")+(Измерения!$H$2:$H$202="недостаточно")),4),""))="Г.2 — достаточность интервалов",1,0)=1,"Пользователь инфраструктуры","Владелец инфраструктуры"))
A7: =IF(IFERROR(_xludf.AGGREGATE(15,6,ROW(Измерения!$H$2:$H$202)/((Измерения!$H$2:$H$202="не соответствует")+(Измерения!$H$2:$H$202="недостаточно")),5),"")="","",5) | B7: =IF(IFERROR(_xludf.AGGREGATE(15,6,ROW(Измерения!$H$2:$H$202)/((Измерения!$H$2:$H$202="не соответствует")+(Измерения!$H$2:$H$202="недостаточно")),5),"")="","",IF(IF(INDEX(Измерения!$J:$J,IFERROR(_xludf.AGGREGATE(15,6,ROW(Измерения!$H$2:$H$202)/((Измерения!$H$2:$H$202="не соответствует")+(Измерения!$H$2:$H$202="недостаточно")),5),""))="Г.2 — достаточность интервалов",1,0)=1,"Е.1 — обусловлено размещением (пользователь)","Е.2 — эксплуатация (владелец)")) | C7: =IFERROR(INDEX(Измерения!$B:$B,IFERROR(_xludf.AGGREGATE(15,6,ROW(Измерения!$H$2:$H$202)/((Измерения!$H$2:$H$202="не соответствует")+(Измерения!$H$2:$H$202="недостаточно")),5),"")),"") | D7: =IFERROR(INDEX(Измерения!$A:$A,IFERROR(_xludf.AGGREGATE(15,6,ROW(Измерения!$H$2:$H$202)/((Измерения!$H$2:$H$202="не соответствует")+(Измерения!$H$2:$H$202="недостаточно")),5),"")),"") | E7: =IF(IFERROR(_xludf.AGGREGATE(15,6,ROW(Измерения!$H$2:$H$202)/((Измерения!$H$2:$H$202="не соответствует")+(Измерения!$H$2:$H$202="недостаточно")),5),"")="","",IF(IF(INDEX(Измерения!$J:$J,IFERROR(_xludf.AGGREGATE(15,6,ROW(Измерения!$H$2:$H$202)/((Измерения!$H$2:$H$202="не соответствует")+(Измерения!$H$2:$H$202="недостаточно")),5),""))="Г.2 — достаточность интервалов",1,0)=1,"Проектное решение по размещению ОК с обеспечением нормируемого расстояния","Устранение несоответствия фактического состояния конструкции")) | F7: =IFERROR(INDEX(Измерения!$C:$C,IFERROR(_xludf.AGGREGATE(15,6,ROW(Измерения!$H$2:$H$202)/((Измерения!$H$2:$H$202="не соответствует")+(Измерения!$H$2:$H$202="недостаточно")),5),""))&": "&INDEX(Измерения!$E:$E,IFERROR(_xludf.AGGREGATE(15,6,ROW(Измерения!$H$2:$H$202)/((Измерения!$H$2:$H$202="не соответствует")+(Измерения!$H$2:$H$202="недостаточно")),5),""))&" "&INDEX(Измерения!$F:$F,IFERROR(_xludf.AGGREGATE(15,6,ROW(Измерения!$H$2:$H$202)/((Измерения!$H$2:$H$202="не соответствует")+(Измерения!$H$2:$H$202="недостаточно")),5),""))&" при норме — "&INDEX(Измерения!$G:$G,IFERROR(_xludf.AGGREGATE(15,6,ROW(Измерения!$H$2:$H$202)/((Измерения!$H$2:$H$202="не соответствует")+(Измерения!$H$2:$H$202="недостаточно")),5),"")),"") | G7: =IF(IFERROR(_xludf.AGGREGATE(15,6,ROW(Измерения!$H$2:$H$202)/((Измерения!$H$2:$H$202="не соответствует")+(Измерения!$H$2:$H$202="недостаточно")),5),"")="","",IF(IF(INDEX(Измерения!$J:$J,IFERROR(_xludf.AGGREGATE(15,6,ROW(Измерения!$H$2:$H$202)/((Измерения!$H$2:$H$202="не соответствует")+(Измерения!$H$2:$H$202="недостаточно")),5),""))="Г.2 — достаточность интервалов",1,0)=1,"Пользователь инфраструктуры","Владелец инфраструктуры"))
A8: =IF(IFERROR(_xludf.AGGREGATE(15,6,ROW(Измерения!$H$2:$H$202)/((Измерения!$H$2:$H$202="не соответствует")+(Измерения!$H$2:$H$202="недостаточно")),6),"")="","",6) | B8: =IF(IFERROR(_xludf.AGGREGATE(15,6,ROW(Измерения!$H$2:$H$202)/((Измерения!$H$2:$H$202="не соответствует")+(Измерения!$H$2:$H$202="недостаточно")),6),"")="","",IF(IF(INDEX(Измерения!$J:$J,IFERROR(_xludf.AGGREGATE(15,6,ROW(Измерения!$H$2:$H$202)/((Измерения!$H$2:$H$202="не соответствует")+(Измерения!$H$2:$H$202="недостаточно")),6),""))="Г.2 — достаточность интервалов",1,0)=1,"Е.1 — обусловлено размещением (пользователь)","Е.2 — эксплуатация (владелец)")) | C8: =IFERROR(INDEX(Измерения!$B:$B,IFERROR(_xludf.AGGREGATE(15,6,ROW(Измерения!$H$2:$H$202)/((Измерения!$H$2:$H$202="не соответствует")+(Измерения!$H$2:$H$202="недостаточно")),6),"")),"") | D8: =IFERROR(INDEX(Измерения!$A:$A,IFERROR(_xludf.AGGREGATE(15,6,ROW(Измерения!$H$2:$H$202)/((Измерения!$H$2:$H$202="не соответствует")+(Измерения!$H$2:$H$202="недостаточно")),6),"")),"") | E8: =IF(IFERROR(_xludf.AGGREGATE(15,6,ROW(Измерения!$H$2:$H$202)/((Измерения!$H$2:$H$202="не соответствует")+(Измерения!$H$2:$H$202="недостаточно")),6),"")="","",IF(IF(INDEX(Измерения!$J:$J,IFERROR(_xludf.AGGREGATE(15,6,ROW(Измерения!$H$2:$H$202)/((Измерения!$H$2:$H$202="не соответствует")+(Измерения!$H$2:$H$202="недостаточно")),6),""))="Г.2 — достаточность интервалов",1,0)=1,"Проектное решение по размещению ОК с обеспечением нормируемого расстояния","Устранение несоответствия фактического состояния конструкции")) | F8: =IFERROR(INDEX(Измерения!$C:$C,IFERROR(_xludf.AGGREGATE(15,6,ROW(Измерения!$H$2:$H$202)/((Измерения!$H$2:$H$202="не соответствует")+(Измерения!$H$2:$H$202="недостаточно")),6),""))&": "&INDEX(Измерения!$E:$E,IFERROR(_xludf.AGGREGATE(15,6,ROW(Измерения!$H$2:$H$202)/((Измерения!$H$2:$H$202="не соответствует")+(Измерения!$H$2:$H$202="недостаточно")),6),""))&" "&INDEX(Измерения!$F:$F,IFERROR(_xludf.AGGREGATE(15,6,ROW(Измерения!$H$2:$H$202)/((Измерения!$H$2:$H$202="не соответствует")+(Измерения!$H$2:$H$202="недостаточно")),6),""))&" при норме — "&INDEX(Измерения!$G:$G,IFERROR(_xludf.AGGREGATE(15,6,ROW(Измерения!$H$2:$H$202)/((Измерения!$H$2:$H$202="не соответствует")+(Измерения!$H$2:$H$202="недостаточно")),6),"")),"") | G8: =IF(IFERROR(_xludf.AGGREGATE(15,6,ROW(Измерения!$H$2:$H$202)/((Измерения!$H$2:$H$202="не соответствует")+(Измерения!$H$2:$H$202="недостаточно")),6),"")="","",IF(IF(INDEX(Измерения!$J:$J,IFERROR(_xludf.AGGREGATE(15,6,ROW(Измерения!$H$2:$H$202)/((Измерения!$H$2:$H$202="не соответствует")+(Измерения!$H$2:$H$202="недостаточно")),6),""))="Г.2 — достаточность интервалов",1,0)=1,"Пользователь инфраструктуры","Владелец инфраструктуры"))
A9: =IF(IFERROR(_xludf.AGGREGATE(15,6,ROW(Измерения!$H$2:$H$202)/((Измерения!$H$2:$H$202="не соответствует")+(Измерения!$H$2:$H$202="недостаточно")),7),"")="","",7) | B9: =IF(IFERROR(_xludf.AGGREGATE(15,6,ROW(Измерения!$H$2:$H$202)/((Измерения!$H$2:$H$202="не соответствует")+(Измерения!$H$2:$H$202="недостаточно")),7),"")="","",IF(IF(INDEX(Измерения!$J:$J,IFERROR(_xludf.AGGREGATE(15,6,ROW(Измерения!$H$2:$H$202)/((Измерения!$H$2:$H$202="не соответствует")+(Измерения!$H$2:$H$202="недостаточно")),7),""))="Г.2 — достаточность интервалов",1,0)=1,"Е.1 — обусловлено размещением (пользователь)","Е.2 — эксплуатация (владелец)")) | C9: =IFERROR(INDEX(Измерения!$B:$B,IFERROR(_xludf.AGGREGATE(15,6,ROW(Измерения!$H$2:$H$202)/((Измерения!$H$2:$H$202="не соответствует")+(Измерения!$H$2:$H$202="недостаточно")),7),"")),"") | D9: =IFERROR(INDEX(Измерения!$A:$A,IFERROR(_xludf.AGGREGATE(15,6,ROW(Измерения!$H$2:$H$202)/((Измерения!$H$2:$H$202="не соответствует")+(Измерения!$H$2:$H$202="недостаточно")),7),"")),"") | E9: =IF(IFERROR(_xludf.AGGREGATE(15,6,ROW(Измерения!$H$2:$H$202)/((Измерения!$H$2:$H$202="не соответствует")+(Измерения!$H$2:$H$202="недостаточно")),7),"")="","",IF(IF(INDEX(Измерения!$J:$J,IFERROR(_xludf.AGGREGATE(15,6,ROW(Измерения!$H$2:$H$202)/((Измерения!$H$2:$H$202="не соответствует")+(Измерения!$H$2:$H$202="недостаточно")),7),""))="Г.2 — достаточность интервалов",1,0)=1,"Проектное решение по размещению ОК с обеспечением нормируемого расстояния","Устранение несоответствия фактического состояния конструкции")) | F9: =IFERROR(INDEX(Измерения!$C:$C,IFERROR(_xludf.AGGREGATE(15,6,ROW(Измерения!$H$2:$H$202)/((Измерения!$H$2:$H$202="не соответствует")+(Измерения!$H$2:$H$202="недостаточно")),7),""))&": "&INDEX(Измерения!$E:$E,IFERROR(_xludf.AGGREGATE(15,6,ROW(Измерения!$H$2:$H$202)/((Измерения!$H$2:$H$202="не соответствует")+(Измерения!$H$2:$H$202="недостаточно")),7),""))&" "&INDEX(Измерения!$F:$F,IFERROR(_xludf.AGGREGATE(15,6,ROW(Измерения!$H$2:$H$202)/((Измерения!$H$2:$H$202="не соответствует")+(Измерения!$H$2:$H$202="недостаточно")),7),""))&" при норме — "&INDEX(Измерения!$G:$G,IFERROR(_xludf.AGGREGATE(15,6,ROW(Измерения!$H$2:$H$202)/((Измерения!$H$2:$H$202="не соответствует")+(Измерения!$H$2:$H$202="недостаточно")),7),"")),"") | G9: =IF(IFERROR(_xludf.AGGREGATE(15,6,ROW(Измерения!$H$2:$H$202)/((Измерения!$H$2:$H$202="не соответствует")+(Измерения!$H$2:$H$202="недостаточно")),7),"")="","",IF(IF(INDEX(Измерения!$J:$J,IFERROR(_xludf.AGGREGATE(15,6,ROW(Измерения!$H$2:$H$202)/((Измерения!$H$2:$H$202="не соответствует")+(Измерения!$H$2:$H$202="недостаточно")),7),""))="Г.2 — достаточность интервалов",1,0)=1,"Пользователь инфраструктуры","Владелец инфраструктуры"))
A10: =IF(IFERROR(_xludf.AGGREGATE(15,6,ROW(Измерения!$H$2:$H$202)/((Измерения!$H$2:$H$202="не соответствует")+(Измерения!$H$2:$H$202="недостаточно")),8),"")="","",8) | B10: =IF(IFERROR(_xludf.AGGREGATE(15,6,ROW(Измерения!$H$2:$H$202)/((Измерения!$H$2:$H$202="не соответствует")+(Измерения!$H$2:$H$202="недостаточно")),8),"")="","",IF(IF(INDEX(Измерения!$J:$J,IFERROR(_xludf.AGGREGATE(15,6,ROW(Измерения!$H$2:$H$202)/((Измерения!$H$2:$H$202="не соответствует")+(Измерения!$H$2:$H$202="недостаточно")),8),""))="Г.2 — достаточность интервалов",1,0)=1,"Е.1 — обусловлено размещением (пользователь)","Е.2 — эксплуатация (владелец)")) | C10: =IFERROR(INDEX(Измерения!$B:$B,IFERROR(_xludf.AGGREGATE(15,6,ROW(Измерения!$H$2:$H$202)/((Измерения!$H$2:$H$202="не соответствует")+(Измерения!$H$2:$H$202="недостаточно")),8),"")),"") | D10: =IFERROR(INDEX(Измерения!$A:$A,IFERROR(_xludf.AGGREGATE(15,6,ROW(Измерения!$H$2:$H$202)/((Измерения!$H$2:$H$202="не соответствует")+(Измерения!$H$2:$H$202="недостаточно")),8),"")),"") | E10: =IF(IFERROR(_xludf.AGGREGATE(15,6,ROW(Измерения!$H$2:$H$202)/((Измерения!$H$2:$H$202="не соответствует")+(Измерения!$H$2:$H$202="недостаточно")),8),"")="","",IF(IF(INDEX(Измерения!$J:$J,IFERROR(_xludf.AGGREGATE(15,6,ROW(Измерения!$H$2:$H$202)/((Измерения!$H$2:$H$202="не соответствует")+(Измерения!$H$2:$H$202="недостаточно")),8),""))="Г.2 — достаточность интервалов",1,0)=1,"Проектное решение по размещению ОК с обеспечением нормируемого расстояния","Устранение несоответствия фактического состояния конструкции")) | F10: =IFERROR(INDEX(Измерения!$C:$C,IFERROR(_xludf.AGGREGATE(15,6,ROW(Измерения!$H$2:$H$202)/((Измерения!$H$2:$H$202="не соответствует")+(Измерения!$H$2:$H$202="недостаточно")),8),""))&": "&INDEX(Измерения!$E:$E,IFERROR(_xludf.AGGREGATE(15,6,ROW(Измерения!$H$2:$H$202)/((Измерения!$H$2:$H$202="не соответствует")+(Измерения!$H$2:$H$202="недостаточно")),8),""))&" "&INDEX(Измерения!$F:$F,IFERROR(_xludf.AGGREGATE(15,6,ROW(Измерения!$H$2:$H$202)/((Измерения!$H$2:$H$202="не соответствует")+(Измерения!$H$2:$H$202="недостаточно")),8),""))&" при норме — "&INDEX(Измерения!$G:$G,IFERROR(_xludf.AGGREGATE(15,6,ROW(Измерения!$H$2:$H$202)/((Измерения!$H$2:$H$202="не соответствует")+(Измерения!$H$2:$H$202="недостаточно")),8),"")),"") | G10: =IF(IFERROR(_xludf.AGGREGATE(15,6,ROW(Измерения!$H$2:$H$202)/((Измерения!$H$2:$H$202="не соответствует")+(Измерения!$H$2:$H$202="недостаточно")),8),"")="","",IF(IF(INDEX(Измерения!$J:$J,IFERROR(_xludf.AGGREGATE(15,6,ROW(Измерения!$H$2:$H$202)/((Измерения!$H$2:$H$202="не соответствует")+(Измерения!$H$2:$H$202="недостаточно")),8),""))="Г.2 — достаточность интервалов",1,0)=1,"Пользователь инфраструктуры","Владелец инфраструктуры"))
A11: =IF(IFERROR(_xludf.AGGREGATE(15,6,ROW(Измерения!$H$2:$H$202)/((Измерения!$H$2:$H$202="не соответствует")+(Измерения!$H$2:$H$202="недостаточно")),9),"")="","",9) | B11: =IF(IFERROR(_xludf.AGGREGATE(15,6,ROW(Измерения!$H$2:$H$202)/((Измерения!$H$2:$H$202="не соответствует")+(Измерения!$H$2:$H$202="недостаточно")),9),"")="","",IF(IF(INDEX(Измерения!$J:$J,IFERROR(_xludf.AGGREGATE(15,6,ROW(Измерения!$H$2:$H$202)/((Измерения!$H$2:$H$202="не соответствует")+(Измерения!$H$2:$H$202="недостаточно")),9),""))="Г.2 — достаточность интервалов",1,0)=1,"Е.1 — обусловлено размещением (пользователь)","Е.2 — эксплуатация (владелец)")) | C11: =IFERROR(INDEX(Измерения!$B:$B,IFERROR(_xludf.AGGREGATE(15,6,ROW(Измерения!$H$2:$H$202)/((Измерения!$H$2:$H$202="не соответствует")+(Измерения!$H$2:$H$202="недостаточно")),9),"")),"") | D11: =IFERROR(INDEX(Измерения!$A:$A,IFERROR(_xludf.AGGREGATE(15,6,ROW(Измерения!$H$2:$H$202)/((Измерения!$H$2:$H$202="не соответствует")+(Измерения!$H$2:$H$202="недостаточно")),9),"")),"") | E11: =IF(IFERROR(_xludf.AGGREGATE(15,6,ROW(Измерения!$H$2:$H$202)/((Измерения!$H$2:$H$202="не соответствует")+(Измерения!$H$2:$H$202="недостаточно")),9),"")="","",IF(IF(INDEX(Измерения!$J:$J,IFERROR(_xludf.AGGREGATE(15,6,ROW(Измерения!$H$2:$H$202)/((Измерения!$H$2:$H$202="не соответствует")+(Измерения!$H$2:$H$202="недостаточно")),9),""))="Г.2 — достаточность интервалов",1,0)=1,"Проектное решение по размещению ОК с обеспечением нормируемого расстояния","Устранение несоответствия фактического состояния конструкции")) | F11: =IFERROR(INDEX(Измерения!$C:$C,IFERROR(_xludf.AGGREGATE(15,6,ROW(Измерения!$H$2:$H$202)/((Измерения!$H$2:$H$202="не соответствует")+(Измерения!$H$2:$H$202="недостаточно")),9),""))&": "&INDEX(Измерения!$E:$E,IFERROR(_xludf.AGGREGATE(15,6,ROW(Измерения!$H$2:$H$202)/((Измерения!$H$2:$H$202="не соответствует")+(Измерения!$H$2:$H$202="недостаточно")),9),""))&" "&INDEX(Измерения!$F:$F,IFERROR(_xludf.AGGREGATE(15,6,ROW(Измерения!$H$2:$H$202)/((Измерения!$H$2:$H$202="не соответствует")+(Измерения!$H$2:$H$202="недостаточно")),9),""))&" при норме — "&INDEX(Измерения!$G:$G,IFERROR(_xludf.AGGREGATE(15,6,ROW(Измерения!$H$2:$H$202)/((Измерения!$H$2:$H$202="не соответствует")+(Измерения!$H$2:$H$202="недостаточно")),9),"")),"") | G11: =IF(IFERROR(_xludf.AGGREGATE(15,6,ROW(Измерения!$H$2:$H$202)/((Измерения!$H$2:$H$202="не соответствует")+(Измерения!$H$2:$H$202="недостаточно")),9),"")="","",IF(IF(INDEX(Измерения!$J:$J,IFERROR(_xludf.AGGREGATE(15,6,ROW(Измерения!$H$2:$H$202)/((Измерения!$H$2:$H$202="не соответствует")+(Измерения!$H$2:$H$202="недостаточно")),9),""))="Г.2 — достаточность интервалов",1,0)=1,"Пользователь инфраструктуры","Владелец инфраструктуры"))
